Workbook

Sheet Stats
A1: Average turnip prices
A2: Monday | B2: a.m. | C2: =IFERROR(ROUND(SUMIFS(Turnips!$A:$A,Turnips!$B:$B,1,Turnips!$C:$C,1)/COUNTIFS(Turnips!$B:$B,1,Turnips!$C:$C,1),2),"no data") -> no data | D2: =IFERROR(ROUND(SUMIF(Turnips!$B:$B,1,Turnips!$A:$A)/COUNTIF(Turnips!$B:$B,1),2),"no data") -> no data
B3: p.m. | C3: =IFERROR(ROUND(SUMIFS(Turnips!$A:$A,Turnips!$B:$B,1,Turnips!$C:$C,2)/COUNTIFS(Turnips!$B:$B,1,Turnips!$C:$C,2),2),"no data") -> no data
A4: Tuesday | B4: a.m. | C4: =IFERROR(ROUND(SUMIFS(Turnips!$A:$A,Turnips!$B:$B,2,Turnips!$C:$C,1)/COUNTIFS(Turnips!$B:$B,2,Turnips!$C:$C,1),2),"no data") -> no data | D4: =IFERROR(ROUND(SUMIF(Turnips!$B:$B,2,Turnips!$A:$A)/COUNTIF(Turnips!$B:$B,2),2),"no data") -> no data
B5: p.m. | C5: =IFERROR(ROUND(SUMIFS(Turnips!$A:$A,Turnips!$B:$B,2,Turnips!$C:$C,2)/COUNTIFS(Turnips!$B:$B,2,Turnips!$C:$C,2),2),"no data") -> no data
A6: Wednesday | B6: a.m. | C6: =IFERROR(ROUND(SUMIFS(Turnips!$A:$A,Turnips!$B:$B,3,Turnips!$C:$C,1)/COUNTIFS(Turnips!$B:$B,3,Turnips!$C:$C,1),2),"no data") -> no data | D6: =IFERROR(ROUND(SUMIF(Turnips!$B:$B,3,Turnips!$A:$A)/COUNTIF(Turnips!$B:$B,3),2),"no data") -> no data
B7: p.m. | C7: =IFERROR(ROUND(SUMIFS(Turnips!$A:$A,Turnips!$B:$B,3,Turnips!$C:$C,2)/COUNTIFS(Turnips!$B:$B,3,Turnips!$C:$C,2),2),"no data") -> no data
A8: Thursday | B8: a.m. | C8: =IFERROR(ROUND(SUMIFS(Turnips!$A:$A,Turnips!$B:$B,4,Turnips!$C:$C,1)/COUNTIFS(Turnips!$B:$B,4,Turnips!$C:$C,1),2),"no data") -> no data | D8: =IFERROR(ROUND(SUMIF(Turnips!$B:$B,4,Turnips!$A:$A)/COUNTIF(Turnips!$B:$B,4),2),"no data") -> no data
B9: p.m. | C9: =IFERROR(ROUND(SUMIFS(Turnips!$A:$A,Turnips!$B:$B,4,Turnips!$C:$C,2)/COUNTIFS(Turnips!$B:$B,4,Turnips!$C:$C,2),2),"no data") -> no data
A10: Friday | B10: a.m. | C10: =IFERROR(ROUND(SUMIFS(Turnips!$A:$A,Turnips!$B:$B,5,Turnips!$C:$C,1)/COUNTIFS(Turnips!$B:$B,5,Turnips!$C:$C,1),2),"no data") -> no data | D10: =IFERROR(ROUND(SUMIF(Turnips!$B:$B,5,Turnips!$A:$A)/COUNTIF(Turnips!$B:$B,5),2),"no data") -> no data
B11: p.m. | C11: =IFERROR(ROUND(SUMIFS(Turnips!$A:$A,Turnips!$B:$B,5,Turnips!$C:$C,2)/COUNTIFS(Turnips!$B:$B,5,Turnips!$C:$C,2),2),"no data") -> no data
A12: Saturday | B12: a.m. | C12: =IFERROR(ROUND(SUMIFS(Turnips!$A:$A,Turnips!$B:$B,6,Turnips!$C:$C,1)/COUNTIFS(Turnips!$B:$B,6,Turnips!$C:$C,1),2),"no data") -> no data | D12: =IFERROR(ROUND(SUMIF(Turnips!$B:$B,6,Turnips!$A:$A)/COUNTIF(Turnips!$B:$B,6),2),"no data") -> no data
B13: p.m. | C13: =IFERROR(ROUND(SUMIFS(Turnips!$A:$A,Turnips!$B:$B,6,Turnips!$C:$C,2)/COUNTIFS(Turnips!$B:$B,6,Turnips!$C:$C,2),2),"no data") -> no data
A15: Catalog | B15: Progress | C15: Catalogued | D15: Total | E15: Remaining
A16: Furniture | B16: =ROUND((C16/D16)*100, 0)&"%" -> 0% | C16: =COUNTA(Furniture!A:A)-1 -> 0 | D16: =COUNTA(Furniture!B:B)-1 -> 1271 | E16: =D16-C16 -> 1271
A17: Wallpapers | B17: =ROUND((C17/D17)*100, 0)&"%" -> 0% | C17: =COUNTA(Wallpapers!A:A)-1 -> 0 | D17: =COUNTA(Wallpapers!B:B)-1 -> 124 | E17: =D17-C17 -> 124
A18: Carpets | B18: =ROUND((C18/D18)*100, 0)&"%" -> 0% | C18: =COUNTA(Carpets!A:A)-1 -> 0 | D18: =COUNTA(Carpets!B:B)-1 -> 118 | E18: =D18-C18 -> 118
A19: Tops | B19: =ROUND((C19/D19)*100, 0)&"%" -> 0% | C19: =COUNTA(Tops!A:A)-1 -> 0 | D19: =COUNTA(Tops!B:B)-1 -> 451 | E19: =D19-C19 -> 451
A20: Bottoms | B20: =ROUND((C20/D20)*100, 0)&"%" -> 0% | C20: =COUNTA(Bottoms!A:A)-1 -> 0 | D20: =COUNTA(Bottoms!B:B)-1 -> 121 | E20: =D20-C20 -> 121
A21: Dresses | B21: =ROUND((C21/D21)*100, 0)&"%" -> 0% | C21: =COUNTA(Dresses!A:A)-1 -> 0 | D21: =COUNTA(Dresses!B:B)-1 -> 97 | E21: =D21-C21 -> 97
A22: Hats | B22: =ROUND((C22/D22)*100, 0)&"%" -> 0% | C22: =COUNTA(Hats!A:A)-1 -> 0 | D22: =COUNTA(Hats!B:B)-1 -> 209 | E22: =D22-C22 -> 209
A23: Accessories | B23: =ROUND((C23/D23)*100, 0)&"%" -> 0% | C23: =COUNTA(Accessories!A:A)-1 -> 0 | D23: =COUNTA(Accessories!B:B)-1 -> 58 | E23: =D23-C23 -> 58
A24: Footwear | B24: =ROUND((C24/D24)*100, 0)&"%" -> 0% | C24: =COUNTA(Footwear!A:A)-1 -> 0 | D24: =COUNTA(Footwear!B:B)-1 -> 97 | E24: =D24-C24 -> 97
A25: Umbrellas | B25: =ROUND((C25/D25)*100, 0)&"%" -> 0% | C25: =COUNTA(Umbrellas!A:A)-1 -> 0 | D25: =COUNTA(Umbrellas!B:B)-1 -> 36 | E25: =D25-C25 -> 36
A26: Paper | B26: =ROUND((C26/D26)*100, 0)&"%" -> 0% | C26: =COUNTA(Paper!A:A)-1 -> 0 | D26: =COUNTA(Paper!B:B)-1 -> 64 | E26: =D26-C26 -> 64
A27: Songs | B27: =ROUND((C27/D27)*100, 0)&"%" -> 0% | C27: =COUNTA(Songs!A:A)-1 -> 0 | D27: =COUNTA(Songs!B:B)-1 -> 91 | E27: =D27-C27 -> 91
A28: Gyroids | B28: =ROUND((C28/D28)*100, 0)&"%" -> 0% | C28: =COUNTA(Gyroids!A:A)-1 -> 0 | D28: =COUNTA(Gyroids!B:B)-1 -> 131 | E28: =D28-C28 -> 131
A30: Museum | B30: Progress | C30: Donated | D30: Total | E30: Remaining
A31: Fossils | B31: =ROUND((C31/D31)*100, 0)&"%" -> 0% | C31: =COUNTA(Fossils!A:A)-1 -> 0 | D31: =COUNTA(Fossils!B:B)-1 -> 67 | E31: =D31-C31 -> 67
A32: Bugs | B32: =ROUND((C32/D32)*100, 0)&"%" -> 0% | C32: =COUNTA(Bugs!A:A)-1 -> 0 | D32: =COUNTA(Bugs!B:B)-1 -> 72 | E32: =D32-C32 -> 72
A33: Fish | B33: =ROUND((C33/D33)*100, 0)&"%" -> 0% | C33: =COUNTA(Fish!A:A)-1 -> 0 | D33: =COUNTA(Fish!B:B)-1 -> 72 | E33: =D33-C33 -> 72
A34: Seafood | B34: =ROUND((C34/D34)*100, 0)&"%" -> 0% | C34: =COUNTA(Seafood!A:A)-1 -> 0 | D34: =COUNTA(Seafood!B:B)-1 -> 30 | E34: =D34-C34 -> 30
A35: Paintings | B35: =ROUND((C35/D35)*100, 0)&"%" -> 0% | C35: =COUNTA(Paintings!A:A)-1 -> 0 | D35: =COUNTA(Paintings!B:B)-1 -> 26 | E35: =D35-C35 -> 26
A37: Emotions | B37: Progress | C37: Learned | D37: Total | E37: Remaining
A38: Emotions | B38: =ROUND((C38/D38)*100, 0)&"%" -> 0% | C38: =COUNTA(Emotions!A:A)-1 -> 0 | D38: =COUNTA(Emotions!B:B)-1 -> 40 | E38: =D38-C38 -> 40
A40: Month-exclusive species counter
B41: Bugs | D41: Fish | F41: Seafood
B42: Outgoing | C42: New | D42: Outgoing | E42: New | F42: Outgoing | G42: New
A43: January | B43: =COUNTIFS(Bugs!E:E,"x",Bugs!F:F,"",Bugs!$A:$A,"") -> 0 | C43: =COUNTIFS(Bugs!P:P,"",Bugs!E:E,"x",Bugs!$A:$A,"") -> 0 | D43: =COUNTIFS(Fish!F:F,"x",Fish!G:G,"",Fish!$A:$A,"") -> 0 | E43: =COUNTIFS(Fish!Q:Q,"",Fish!F:F,"x",Fish!$A:$A,"") -> 1 | F43: =COUNTIFS(Seafood!E:E,"x",Seafood!F:F,"",Seafood!$A:$A,"") -> 1 | G43: =COUNTIFS(Seafood!P:P,"",Seafood!E:E,"x",Seafood!$A:$A,"") -> 0
A44: February | B44: =COUNTIFS(Bugs!F:F,"x",Bugs!G:G,"",Bugs!$A:$A,"") -> 3 | C44: =COUNTIFS(Bugs!E:E,"",Bugs!F:F,"x",Bugs!$A:$A,"") -> 0 | D44: =COUNTIFS(Fish!G:G,"x",Fish!H:H,"",Fish!$A:$A,"") -> 5 | E44: =COUNTIFS(Fish!F:F,"",Fish!G:G,"x",Fish!$A:$A,"") -> 0 | F44: =COUNTIFS(Seafood!F:F,"x",Seafood!G:G,"",Seafood!$A:$A,"") -> 2 | G44: =COUNTIFS(Seafood!E:E,"",Seafood!F:F,"x",Seafood!$A:$A,"") -> 0
...

Sheet Turnips
A1: Price | B1: Day | C1: Time
Q2: =COUNTIFS($B:$B,6,$C:$C,1) -> 0 | R2: =COUNTIFS($B:$B,6,$C:$C,2) -> 0
Q3: =SUMIFS(Turnips!$A:$A,Turnips!$B:$B,6,Turnips!$C:$C,1)/COUNTIFS(Turnips!$B:$B,6,Turnips!$C:$C,1) -> #DIV/0! | R3: =SUMIFS(Turnips!$A:$A,Turnips!$B:$B,6,Turnips!$C:$C,2)/COUNTIFS(Turnips!$B:$B,6,Turnips!$C:$C,2) -> #DIV/0!

Sheet Furniture
A1: Catalogued? | B1: Name
B2: ? Block
B3: 1-Up Mushroom
B4: 24-hour-shop counter
B5: 24-hour-shop model
B6: 24-hour-shop sign
B7: Afternoon-tea set
B8: Air conditioner
B9: Alarm clock
B10: Aloe
B11: Alpine bed
B12: Alpine chair
B13: Alpine closet
... B1272: Zodiac tiger

Sheet Wallpapers
A1: Catalogued? | B1: Name
B2: Alpine wall
B3: Ancient wall
B4: Arched window
B5: Astro wall
B6: Autumn wall
B7: Backgammon wall
B8: Backyard fence
B9: Balloon wall
B10: Bamboo wall
B11: Basement wall
B12: Bathhouse wall
B13: Blue tarp
... B125: Wood paneling

Sheet Carpets
A1: Catalogued? | B1: Name
B2: Alpine rug
B3: Ancient tile
B4: Astro floor
B5: Autumn floor
B6: Backyard lawn
B7: Balloon floor
B8: Bamboo flooring
B9: Basement floor
B10: Bath tile
B11: Birch flooring
B12: Block floor
B13: Blue flooring
... B119: Wildflower floor

Sheet Tops
A1: Catalogued? | B1: Name
B2: 24-hour-shop uniform
B3: A tee
B4: Acid-washed jacket
B5: After-school jacket
B6: Airy tee
B7: Amethyst shirt
B8: Amethyst tee
B9: Aqua polka tank
B10: Aqua polka tee
B11: Arctic-camo shirt
B12: Arctic-camo tee
B13: Argyle knit shirt
... B452: Zipper tank

Sheet Bottoms
A1: Catalogued? | B1: Name
B2: Acid-washed pants
B3: Aloha shorts
B4: Arctic-camo pants
B5: Armor pants
B6: Baseball pants
B7: Basketball shorts
B8: Bear-costume pants
B9: Black formal pants
B10: Black formal skirt
B11: Black track pants
B12: Black-denim pants
B13: Black-denim skirt
... B122: Zebra pants

Sheet Dresses
A1: Catalogued? | B1: Name
B2: Academy uniform
B3: Alpinist dress
B4: Ballet outfit
B5: Bathrobe
B6: Black-velvet dress
B7: Blossom dress
B8: Blossoming dress
B9: Blue dotted dress
B10: Blue lace-up dress
B11: Blue party dress
B12: Blue retro dress
B13: Butterfly dress
... B98: Yodel dress

Sheet Hats
A1: Catalogued? | B1: Name
B2: 1-Up cap
B3: Afro cap
B4: Afro wig
B5: Alpinist hat
B6: Baby's hat
B7: Badge hat
B8: Balloon hat
B9: Banana-split hat
B10: Bandana
B11: Batter's helmet
B12: Bear cap
B13: Beret
... B210: Yellow-pumpkin head

Sheet Accessories
A1: Catalogued? | B1: Name
B2: 3D glasses
B3: Aviator shades
B4: Bad bro's stache
B5: Ballroom mask
B6: Bandage
B7: Beak
B8: Big bro's mustache
B9: Blue frames
B10: Brown glasses
B11: Cucumber pack
B12: Curly mustache
B13: Cyber shades
... B59: Yellow glasses

Sheet Footwear
A1: Catalogued? | B1: Name
B2: Argyle socks
B3: Argyle tights
B4: Armor shoes
B5: Ballet slippers
B6: Basketball shoes
B7: Beige tights
B8: Black ankle socks
B9: Black leggings
B10: Black loafers
B11: Black pumps
B12: Black rain boots
B13: Black stockings
... B98: Zap boots

Sheet Umbrellas
A1: Catalogued? | B1: Name
B2: Bat umbrella
B3: Beach umbrella
B4: Blue dot parasol
B5: Blue umbrella
B6: Busted umbrella
B7: Camo umbrella
B8: Candy umbrella
B9: Daisy umbrella
B10: Eggy parasol
B11: Elegant umbrella
B12: Flame umbrella
B13: Forest umbrella
... B37: Zebra umbrella

Sheet Paper
A1: Catalogued? | B1: Name
B2: Academy paper
B3: Airmail paper
B4: Bathtub paper
B5: Bejeweled paper
B6: Birthday card
B7: Bubble paper
B8: Buttercup paper
B9: Butterfly paper
B10: Camouflage paper
B11: Card paper
B12: Chic paper
B13: Cloudy paper
... B65: Weathered paper

Sheet Songs
A1: Catalogued? | B1: Name | C1: Mood
B2: Agent K.K. | C2: Hard to say
B3: Aloha K.K. | C3: Lazy
B4: Bubblegum K.K. | C4: Good
B5: Café K.K. | C5: Good
B6: Comrade K.K. | C6: A little sad
B7: DJ K.K. | C7: Grumpy
B8: Forest Life | C8: Lazy
B9: Go K.K. Rider | C9: Grumpy
B10: Hypno K.K. | C10: Request only
B11: I Love You | C11: Lazy
B12: Imperial K.K. | C12: Grumpy
B13: K.K. Adventure | C13: Grumpy
... B92: Wandering | C92: Lazy

Sheet Gyroids
A1: Catalogued? | B1: Name
B2: Mega alloid
B3: Mini alloid
B4: Tall alloid
B5: Mega bovoid
B6: Tall bovoid
B7: Bowtoid
B8: Mega bowtoid
B9: Mini bowtoid
B10: Tall bowtoid
B11: Buzzoid
B12: Mega buzzoid
B13: Mini buzzoid
... B132: Tall brewstoid

Sheet Fossils
A1: Donated? | B1: Name
B2: Amber
B3: Ammonite
B4: Ankylo skull
B5: Ankylo torso
B6: Ankylo tail
B7: Apato skull
B8: Apato torso
B9: Apato tail
B10: Archaeopteryx
B11: Archelon skull
B12: Archelon torso
B13: Coprolite
... B68: Trilobite

Sheet Bugs
A1: Donated? | B1: Name | C1: Location | D1: Time | E1: Jan | F1: Feb | G1: Mar | H1: Apr | I1: May | J1: Jun | K1: Jul | L1: Aug | M1: Sep | N1: Oct | O1: Nov | P1: Dec
B2: Agrias Butterfly | C2: Flying near flowers | D2: 8am - 5pm | J2: x | K2: x | L2: x | M2: x
B3: Ant | C3: On rotten food | D3: All day | E3: x | F3: x | G3: x | H3: x | I3: x | J3: x | K3: x | L3: x | M3: x | N3: x | O3: x | P3: x
B4: Bagworm | C4: In trees | D4: All day | E4: x | F4: x | N4: x | O4: x | P4: x
B5: Banded Dragonfly | C5: Flying | D5: 8am - 5pm | K5: x | L5: x
B6: Bee | C6: In trees | D6: All day | E6: x | F6: x | G6: x | H6: x | I6: x | J6: x | K6: x | L6: x | M6: x | N6: x | O6: x | P6: x
B7: Bell Cricket | C7: On the ground | D7: 5pm - 8am | M7: x | N7: x
B8: Birdwing Butterfly | C8: Flying | D8: 8am - 4pm | J8: x | K8: x | L8: x | M8: x
B9: Brown Cicada | C9: On trees | D9: 8am - 5pm | K9: x | L9: x
B10: Centipede | C10: Under rocks | D10: 4pm - 11pm | E10: x | F10: x | J10: x | K10: x | L10: x | M10: x | N10: x | O10: x | P10: x
B11: Cicada Shell | C11: On trees | D11: All day | K11: x | L11: x
B12: Common Butterfly | C12: Flying near flowers | D12: 4am - 7pm | G12: x | H12: x | I12: x | J12: x | M12: x
B13: Cricket | C13: On the ground | D13: 5pm - 8am | M13: x | N13: x | O13: x
B14: Cyclommatus Stag | C14: On palm trees | D14: 5pm - 8am | J14: x | K14: x | L14: x
B15: Darner Dragonfly | C15: Flying | D15: 8am - 5pm | J15: x | K15: x | L15: x
B16: Diving Beetle | C16: Rivers and ponds | D16: 8am - 5pm | I16: x | J16: x | K16: x | L16: x | M16: x
B17: Dung Beetle | C17: Snow balls | D17: 5pm - 8am | E17: x | F17: x | P17: x
B18: Emperor Butterfly | C18: Flying | D18: 8pm - 7am | J18: x | K18: x | L18: x | M18: x
B19: Evening Cicada | C19: On trees | D19: 4pm - 7pm | K19: x | L19: x
B20: Firefly | C20: Flying near river | D20: 7pm - 4am | J20: x
B21: Flea | C21: On villagers | D21: All day | G21: x | H21: x | I21: x | J21: x | K21: x | L21: x | M21: x | N21: x | O21: x
B22: Fly | C22: Flying near trash | D22: All day | E22: x | F22: x | G22: x | H22: x | I22: x | J22: x | K22: x | L22: x | M22: x | N22: x | O22: x | P22: x
B23: Fruit Beetle | C23: On trees | D23: All day | K23: x | L23: x | M23: x
B24: Giant Cicada | C24: On trees | D24: 8am - 5pm | K24: x | L24: x
B25: Giant Petaltail | C25: Flying | D25: 5pm - 7pm | L25: x | M25: x | N25: x
B26: Giant Stag | C26: On trees | D26: 11pm - 7am | K26: x | L26: x
B27: Golden Stag | C27: On palm trees | D27: 5pm - 8am | J27: x | K27: x | L27: x
B28: Goliath Beetle | C28: On palm trees | D28: 7pm - 8am | J28: x | K28: x | L28: x | M28: x
B29: Grasshopper | C29: On the ground | D29: 8am - 5pm | K29: x | L29: x | M29: x
B30: Hermit Crab | C30: On the beach | D30: 7pm - 8am | E30: x | F30: x | G30: x | H30: x | I30: x | J30: x | K30: x | L30: x | M30: x | N30: x | O30: x | P30: x
B31: Honeybee | C31: Flying near flowers | D31: 8am - 5pm | G31: x | H31: x | I31: x | J31: x | K31: x
B32: Horned Atlas | C32: On palm trees | D32: 5pm - 8am | J32: x | K32: x | L32: x
B33: Horned Dynastid | C33: On trees | D33: 7pm - 8am | J33: x | K33: x | L33: x
B34: Horned Elephant | C34: On palm trees | D34: 5pm - 8am | J34: x | K34: x | L34: x
B35: Horned Hercules | C35: On palm trees | D35: 5pm - 8am | J35: x | K35: x | L35: x
B36: House Centipede | C36: Under rocks | D36: 7pm - 8am | L36: x | M36: x | N36: x
B37: Jewel Beetle | C37: On trees | D37: 8am - 5pm | K37: x | L37: x
B38: Ladybug | C38: On flowers | D38: 8am - 5pm | G38: x | H38: x | I38: x | J38: x | N38: x
B39: Lantern Fly | C39: On trees | D39: 4pm - 8am | J39: x | K39: x | L39: x | M39: x
B40: Long Locust | C40: On the ground | D40: 8am - 7pm | I40: x | J40: x | K40: x | L40: x | M40: x | N40: x | O40: x
...

Sheet Fish
A1: Donated? | B1: Name | C1: Location | D1: Size | E1: Time | F1: Jan | G1: Feb | H1: Mar | I1: Apr | J1: May | K1: Jun | L1: Jul | M1: Aug | N1: Sep | O1: Oct | P1: Nov | Q1: Dec
B2: Angelfish | C2: River | D2: 2 | E2: 4pm - 9am | J2: x | K2: x | L2: x | M2: x | N2: x | O2: x
B3: Arapaima | C3: River | D3: 6 | E3: 4pm - 9am | L3: x | M3: x | N3: x
B4: Arowana | C4: River | D4: 3 | E4: 4pm - 9am (until Sep 15) | K4: x | L4: x | M4: x | N4: x
B5: Barbel Steed | C5: River | D5: 3 | E5: All day | F5: x | G5: x | H5: x | I5: x | J5: x | K5: x | L5: x | M5: x | N5: x | O5: x | P5: x | Q5: x
B6: Barred Knifejaw | C6: Ocean | D6: 3 | E6: All day | H6: x | I6: x | J6: x | K6: x | L6: x | M6: x | N6: x | O6: x | P6: x
B7: Bitterling | C7: River | D7: 1 | E7: All day | F7: x | G7: x | Q7: x
B8: Black Bass | C8: River | D8: 4 | E8: All day | F8: x | G8: x | H8: x | I8: x | J8: x | K8: x | L8: x | M8: x | N8: x | O8: x | P8: x | Q8: x
B9: Blowfish | C9: Ocean | D9: 3 | E9: All day | F9: x | G9: x | P9: x | Q9: x
B10: Blue Marlin | C10: Ocean | D10: 6 | E10: All day | K10: x | L10: x | M10: x | N10: x
B11: Bluegill | C11: River | D11: 2 | E11: 9am - 4pm | F11: x | G11: x | H11: x | I11: x | J11: x | K11: x | L11: x | M11: x | N11: x | O11: x | P11: x | Q11: x
B12: Butterflyfish | C12: Ocean | D12: 2 | E12: All day | I12: x | J12: x | K12: x | L12: x | M12: x | N12: x
B13: Carp | C13: River | D13: 4 | E13: All day | F13: x | G13: x | H13: x | I13: x | J13: x | K13: x | L13: x | M13: x | N13: x | O13: x | P13: x | Q13: x
B14: Catfish | C14: Lake | D14: 4 | E14: 4pm - 9am | H14: x | I14: x | J14: x | K14: x | L14: x | M14: x | N14: x | O14: x
B15: Char | C15: Waterfall | D15: 3 | E15: 4am - 9am, 4pm - 9pm | H15: x | I15: x | J15: x | K15: x | N15: x | O15: x | P15: x
B16: Cherry Salmon | C16: River | D16: 3 | E16: All day | H16: x | I16: x | J16: x | K16: x | N16: x | O16: x | P16: x
B17: Clownfish | C17: Ocean | D17: 1 | E17: All day | I17: x | J17: x | K17: x | L17: x | M17: x | N17: x
B18: Coelacanth | C18: Ocean (rain) | D18: 6 | E18: 4pm - 9am | F18: x | G18: x | H18: x | I18: x | J18: x | K18: x | L18: x | M18: x | N18: x | O18: x | P18: x | Q18: x
B19: Crawfish | C19: Pond | D19: 2 | E19: All day (until Sep 15) | I19: x | J19: x | K19: x | L19: x | M19: x | N19: x
B20: Crucian Carp | C20: River | D20: 2 | E20: All day | F20: x | G20: x | H20: x | I20: x | J20: x | K20: x | L20: x | M20: x | N20: x | O20: x | P20: x | Q20: x
B21: Dab | C21: Ocean | D21: 3 | E21: All day | F21: x | G21: x | H21: x | I21: x | P21: x | Q21: x
B22: Dace | C22: River | D22: 3 | E22: 4pm - 9am | F22: x | G22: x | H22: x | I22: x | J22: x | K22: x | L22: x | M22: x | N22: x | O22: x | P22: x | Q22: x
B23: Dorado | C23: River | D23: 5 | E23: 4am - 9pm | K23: x | L23: x | M23: x | N23: x
B24: Eel | C24: River | D24: Thin | E24: 4pm - 9am (until Sep 15) | K24: x | L24: x | M24: x | N24: x
B25: Football Fish | C25: Ocean | D25: 4 | E25: 4pm - 9am | F25: x | G25: x | H25: x | P25: x | Q25: x
B26: Freshwater Goby | C26: River | D26: 2 | E26: 4pm - 9am | F26: x | G26: x | H26: x | I26: x | J26: x | K26: x | L26: x | M26: x | N26: x | O26: x | P26: x | Q26: x
B27: Frog | C27: Pond | D27: 1 | E27: All day | J27: x | K27: x | L27: x | M27: x
B28: Gar | C28: Lake | D28: 6 | E28: 4pm - 9am | K28: x | L28: x | M28: x | N28: x
B29: Giant Snakehead | C29: Lake | D29: 5 | E29: 9am - 4pm | K29: x | L29: x | M29: x
B30: Giant Trevally | C30: Island | D30: 5 | E30: All day | F30: x | G30: x | H30: x | I30: x | J30: x | K30: x | L30: x | M30: x | N30: x | O30: x | P30: x | Q30: x
B31: Goldfish | C31: River | D31: 1 | E31: All day | F31: x | G31: x | H31: x | I31: x | J31: x | K31: x | L31: x | M31: x | N31: x | O31: x | P31: x | Q31: x
B32: Guppy | C32: River | D32: 1 | E32: 9am - 4pm | I32: x | J32: x | K32: x | L32: x | M32: x | N32: x | O32: x | P32: x
B33: Hammerhead Shark | C33: Ocean | D33: Fin | E33: 4pm - 9am | J33: x | K33: x | L33: x | M33: x
B34: Horse Mackerel | C34: Ocean | D34: 2 | E34: All day | F34: x | G34: x | H34: x | I34: x | J34: x | K34: x | L34: x | M34: x | N34: x | O34: x | P34: x | Q34: x
B35: Killifish | C35: Pond | D35: 1 | E35: All day | I35: x | J35: x | K35: x | L35: x | M35: x
B36: King Salmon | C36: River | D36: 6 | E36: All day | N36: x
B37: Koi | C37: River | D37: 4 | E37: 4pm - 9am | F37: x | G37: x | H37: x | I37: x | J37: x | K37: x | L37: x | M37: x | N37: x | O37: x | P37: x | Q37: x
B38: Loach | C38: River | D38: 2 | E38: All day | H38: x | I38: x | J38: x
B39: Mitten Crab | C39: River | D39: 2 | E39: 4pm - 9am (after Sep 15) | N39: x | O39: x | P39: x
B40: Moray Eel | C40: Ocean | D40: 5 | E40: All Day | K40: x | L40: x | M40: x | N40: x | O40: x
...

Sheet Seafood
A1: Donated? | B1: Name | C1: Size | D1: Time | E1: Jan | F1: Feb | G1: Mar | H1: Apr | I1: May | J1: Jun | K1: Jul | L1: Aug | M1: Sep | N1: Oct | O1: Nov | P1: Dec
B2: Abalone | C2: Medium | D2: 4pm - 9am | E2: x | F2: x | G2: x | H2: x | I2: x | J2: x | K2: x | L2: x | M2: x | N2: x | O2: x | P2: x
B3: Acorn Barnacle | C3: Tiny | D3: All day | E3: x | F3: x | G3: x | H3: x | I3: x | J3: x | K3: x | L3: x | M3: x | N3: x | O3: x | P3: x
B4: Chambered Nautilus | C4: Medium | D4: All day | E4: x | F4: x | G4: x | H4: x | I4: x | J4: x | K4: x | L4: x | M4: x | N4: x | O4: x | P4: x
B5: Clam | C5: Small | D5: All day | E5: x | F5: x | G5: x | H5: x | M5: x | N5: x | O5: x | P5: x
B6: Ear Shell | C6: Small | D6: 4pm - 9am | E6: x | F6: x | G6: x | H6: x | I6: x | J6: x | K6: x | L6: x | M6: x | N6: x | O6: x | P6: x
B7: Flatworm | C7: Small | D7: 4pm - 9am | J7: x | K7: x | L7: x | M7: x
B8: Giant Isopod | C8: Medium | D8: All day | E8: x | F8: x | G8: x | H8: x | I8: x | J8: x | K8: x | L8: x | M8: x | N8: x | O8: x | P8: x
B9: Giant Spider Crab | C9: V.Large | D9: All day | G9: x | H9: x
B10: Horsehair Crab | C10: Medium | D10: All day | E10: x | F10: x | G10: x | H10: x | O10: x | P10: x
B11: Horseshoe Crab | C11: Medium | D11: 9pm - 4am | K11: x | L11: x | M11: x
B12: Lobster | C12: Large | D12: All day | E12: x | F12: x | G12: x | H12: x | I12: x | J12: x | K12: x | L12: x | M12: x | N12: x | O12: x | P12: x
B13: Mantis Shrimp | C13: Small | D13: 4pm - 9am | E13: x | F13: x | G13: x | H13: x | I13: x | J13: x | K13: x | L13: x | M13: x | N13: x | O13: x | P13: x
B14: Octopus | C14: Medium | D14: All day | E14: x | G14: x | H14: x | I14: x | J14: x | K14: x | M14: x | N14: x | O14: x | P14: x
B15: Oyster | C15: Small | D15: All day | E15: x | F15: x | M15: x | N15: x | O15: x | P15: x
B16: Pearl Oyster | C16: Small | D16: All day | E16: x | F16: x | G16: x | H16: x | I16: x | J16: x | K16: x | L16: x | M16: x | N16: x | O16: x | P16: x
B17: Red King Crab | C17: Large | D17: All day | E17: x | F17: x | G17: x | O17: x | P17: x
B18: Spiny Lobster | C18: Large | D18: 4pm - 9am | M18: x | N18: x | O18: x | P18: x
B19: Scallop | C19: Medium | D19: All day | E19: x | F19: x | G19: x | H19: x | I19: x | J19: x | K19: x | L19: x | M19: x | N19: x | O19: x | P19: x
B20: Sea Anemone | C20: Medium | D20: All day | E20: x | F20: x | G20: x | H20: x | I20: x | J20: x | K20: x | L20: x | M20: x | N20: x | O20: x | P20: x
B21: Sea Cucumber | C21: Medium | D21: All day | E21: x | F21: x | G21: x | H21: x | O21: x | P21: x
B22: Sea Grapes | C22: Small | D22: All day | J22: x | K22: x | L22: x | M22: x
B23: Sea Slug | C23: Small | D23: All day | E23: x | F23: x | G23: x | H23: x | I23: x | J23: x | K23: x | L23: x | M23: x | N23: x | O23: x | P23: x
B24: Sea Star | C24: Small | D24: All day | E24: x | F24: x | G24: x | H24: x | I24: x | J24: x | K24: x | L24: x | M24: x | N24: x | O24: x | P24: x
B25: Sea Urchin | C25: Small | D25: All day | I25: x | J25: x | K25: x | L25: x | M25: x
B26: Seaweed | C26: Large | D26: All day | E26: x | F26: x | G26: x | H26: x | I26: x | J26: x | K26: x | O26: x | P26: x
B27: Snow Crab | C27: Large | D27: All day | E27: x | F27: x | G27: x | H27: x | O27: x | P27: x
B28: Spotted Garden Eel | C28: Small | D28: All day | E28: x | F28: x | G28: x | H28: x | I28: x | J28: x | K28: x | L28: x | M28: x | N28: x | O28: x | P28: x
B29: Sweet Shrimp | C29: Small | D29: 4pm - 9am | E29: x | F29: x | M29: x | N29: x | O29: x | P29: x
B30: Tiger Prawn | C30: Small | D30: 4pm - 9am | J30: x | K30: x | L30: x | M30: x
B31: Turban Shell | C31: Small | D31: 4pm - 9am | E31: x | F31: x | G31: x | H31: x | I31: x | L31: x | M31: x | N31: x | O31: x | P31: x

Sheet Paintings
A1: Donated? | B1: Name | C1: Genuine | D1: Fake
B2: Amazing Painting | C2: Man in white is on the right | D2: Man in white is on the left
B3: Basic Painting | C3: One arm is bent | D3: Both arms are bent at his sides
B4: Calm Painting | C4: Always genuine | D4: No fake
B5: Common Painting | C5: Always genuine | D5: No fake
B6: Dynamic Painting | C6: Mt Fuji is small | D6: Mt Fuji is large and takes up most of space under the wave
B7: Famous Painting | C7: Fingers point to bottom right of picture | D7: Fingers pointing to bottom left of picture
B8: Fine Painting | C8: Always genuine | D8: No fake
B9: Flowery Painting | C9: Always genuine | D9: No fake
B10: Graceful Painting | C10: Looking to the right | D10: Looking to the left
B11: Jolly Painting | C11: Nose is made of green vegetable | D11: Nose is made of carrot and has leaves hanging out
B12: Moody Painting | C12: Always genuine | D12: No fake
B13: Moving Painting | C13: Shell is right way up | D13: Upside-down shell
... B27: Worthy Painting | C27: Always genuine | D27: No fake

Sheet Emotions
A1: Learned? | B1: Emotion
B2: Aggravation
B3: Agreement
B4: Anger
B5: Bashfulness
B6: Cold Chill
B7: Curiosity
B8: Daydreaming
B9: Delight
B10: Disagreement
B11: Disbelief
B12: Distress
B13: Fearful
... B41: Worry
